<?xml version="1.0" encoding="utf-8"?>
<!-- This URDF was automatically created by SolidWorks to URDF Exporter! Originally created by Stephen Brawner (brawner@gmail.com) 
     Commit Version: 1.6.0-1-g15f4949  Build Version: 1.6.7594.29634
     For more information, please see http://wiki.ros.org/sw_urdf_exporter -->
<robot
  name="mousebot">
  <link
    name="mousebot">
    <inertial>
      <origin
        xyz="0.0097506 0 0.010314"
        rpy="0 0 0" />
      <mass
        value="0.147" />
      <inertia
        ixx="7.4724E-05"
        ixy="3.4149E-21"
        ixz="3.363E-08"
        iyy="0.00012775"
        iyz="-3.5117E-21"
        izz="0.00019203" />
    </inertial>
    <visual>
      <origin
        xyz="0 0 0"
        rpy="0 0 0" />
      <geometry>
        <mesh
          filename="package://mousebot/meshes/mousebot.STL" />
      </geometry>
      <material
        name="">
        <color
          rgba="0.79216 0.81961 0.93333 1" />
      </material>
    </visual>
    <collision>
      <origin
        xyz="0 0 0"
        rpy="0 0 0" />
      <geometry>
        <mesh
          filename="package://mousebot/meshes/mousebot_col.STL" />
      </geometry>
    </collision>
  </link>
  
  <link
    name="R_wheel">
    <inertial>
      <origin
        xyz="-2.1684E-19 -0.00635 -6.9389E-18"
        rpy="0 0 0" />
      <mass
        value="0.010055" />
      <inertia
        ixx="7.6865E-07"
        ixy="2.2411E-23"
        ixz="1.4542E-23"
        iyy="1.267E-06"
        iyz="4.8169E-39"
        izz="7.6865E-07" />
    </inertial>
    <visual>
      <origin
        xyz="0 0 0"
        rpy="0 0 0" />
      <geometry>
        <mesh
          filename="package://mousebot/meshes/R_wheel.STL" />
      </geometry>
      <material
        name="">
        <color
          rgba="0.79216 0.81961 0.93333 1" />
      </material>
    </visual>
    <collision>
      <origin
        xyz="0 0 0"
        rpy="0 0 0" />
      <geometry>
        <mesh
          filename="package://mousebot/meshes/R_wheel_col.STL" />
      </geometry>
    </collision>
  </link>
  <joint
    name="R_wheel_cont"
    type="continuous">
    <origin
      xyz="0 -0.03175 0.0127"
      rpy="0 0 0" />
    <parent
      link="mousebot" />
    <child
      link="R_wheel" />
    <axis
      xyz="0 1 0" />
    <limit
      effort="0"
      velocity="200" />
  </joint>
  
  <link
    name="L_wheel">
    <inertial>
      <origin
        xyz="2.1684E-19 0.00635 -1.3878E-17"
        rpy="0 0 0" />
      <mass
        value="0.010055" />
      <inertia
        ixx="7.6865E-07"
        ixy="5.6028E-24"
        ixz="9.9526E-23"
        iyy="1.267E-06"
        iyz="-1.1206E-23"
        izz="7.6865E-07" />
    </inertial>
    <visual>
      <origin
        xyz="0 0 0"
        rpy="0 0 0" />
      <geometry>
        <mesh
          filename="package://mousebot/meshes/L_wheel.STL" />
      </geometry>
      <material
        name="">
        <color
          rgba="0.79216 0.81961 0.93333 1" />
      </material>
    </visual>
    <collision>
      <origin
        xyz="0 0 0"
        rpy="0 0 0" />
      <geometry>
        <mesh
          filename="package://mousebot/meshes/L_wheel_col.STL" />
      </geometry>
    </collision>
  </link>
  <joint
    name="L_wheel_cont"
    type="continuous">
    <origin
      xyz="0 0.03175 0.0127"
      rpy="0 0 0" />
    <parent
      link="mousebot" />
    <child
      link="L_wheel" />
    <axis
      xyz="0 1 0" />
    <limit
      effort="0"
      velocity="200" />
  </joint>
  
    <joint name="hokuyo_joint" type="fixed">
    <axis xyz="0 1 0" />
    <origin xyz="0 0 0.03" rpy="0 0 3.1415926"/>
    <parent link="mousebot"/>
    <child link="hokuyo_link"/>
  </joint>
  <link name="hokuyo_link">
    <collision>
      <origin xyz="0 0 0" rpy="0 0 0"/>
      <geometry>
    <box size="0.01 0.01 0.01"/>
      </geometry>
    </collision>
    <visual>
      <origin xyz="0 0 0" rpy="0 0 0"/>
      <geometry>
        <mesh filename="package://mousebot/meshes/hokuyo.dae" scale="0.1 0.1 0.1"/>
      </geometry>
    </visual>
    <inertial>
      <mass value="1e-5" />
      <origin xyz="0 0 0" rpy="0 0 0"/>
      <inertia ixx="1e-6" ixy="0" ixz="0" iyy="1e-6" iyz="0" izz="1e-6" />
    </inertial>
  </link>
  
  <gazebo reference="mousebot">
    <material>Gazebo/Green</material>
  </gazebo>

  <gazebo reference="R_wheel">
    <material>Gazebo/DarkGrey</material>
    <mu1>1.0</mu1>
    <mu2>1.0</mu2>
    <kp>1000000.0</kp>
    <kd>100.0</kd>
    <minDepth>0.001</minDepth>
    <maxVel>5.0</maxVel>
  </gazebo>

  <gazebo reference="L_wheel">
    <material>Gazebo/DarkGrey</material>
    <mu1>1.0</mu1>
    <mu2>1.0</mu2>
    <kp>1000000.0</kp>
    <kd>100.0</kd>
    <minDepth>0.001</minDepth>
    <maxVel>5.0</maxVel>
  </gazebo>
  
  <gazebo reference="hokuyo_link">
    <sensor type="gpu_ray" name="head_hokuyo_sensor">
      <pose>0 0 0 0 0 0</pose>
      <visualize>true</visualize>
      <update_rate>40</update_rate>
      <ray>
        <scan>
          <horizontal>
            <samples>361</samples>
            <resolution>1</resolution>
            <min_angle>-3.1415926</min_angle>
            <max_angle>3.1415926</max_angle>
          </horizontal>
        </scan>
        <range>
          <min>0.05</min>
          <max>0.3</max>
          <resolution>0.01</resolution>
        </range>
        <noise>
          <type>gaussian</type>
          <!-- Noise parameters based on published spec for Hokuyo laser
               achieving "+-30mm" accuracy at range < 10m.  A mean of 0.0m and
               stddev of 0.01m will put 99.7% of samples within 0.03m of the true
               reading. -->
          <mean>0.0</mean>
          <stddev>0.001</stddev>
        </noise>
      </ray>
      <plugin name="gazebo_ros_head_hokuyo_controller" filename="libgazebo_ros_gpu_laser.so">
        <topicName>scan</topicName>
        <frameName>hokuyo_link</frameName>
      </plugin>
    </sensor>
  </gazebo>

  <gazebo>
      <plugin name="differential_drive_controller" filename="libgazebo_ros_diff_drive.so">
      <alwaysOn>true</alwaysOn>
      <updateRate>10</updateRate>
      <leftJoint>L_wheel_cont</leftJoint>
      <rightJoint>R_wheel_cont</rightJoint>
      <wheelSeparation>0.0762</wheelSeparation>
      <wheelDiameter>0.03175</wheelDiameter>
      <torque>10</torque>
      <commandTopic>cmd_vel</commandTopic>
      <odometryTopic>odom</odometryTopic>
      <odometryFrame>odom</odometryFrame>
      <robotBaseFrame>mousebot</robotBaseFrame>
      <odometrySource>encoder</odometrySource>
    </plugin>
  </gazebo>
  
</robot>
